[
  {
    "command": "pip install --no-build-isolation -e ./python",
    "success": false,
    "stdout": "Looking in indexes: https://repo.huaweicloud.com/repository/pypi/simple/\nObtaining file:///app/repo_to_process/python\n  Checking if build backend supports build_editable: started\n  Checking if build backend supports build_editable: finished with status 'done'\n  Preparing editable metadata (pyproject.toml): started\n  Preparing editable metadata (pyproject.toml): finished with status 'error'\n",
    "stderr": "  error: subprocess-exited-with-error\n  \n  × Preparing editable metadata (pyproject.toml) did not run successfully.\n  │ exit code: 1\n  ╰─> [16 lines of output]\n      Traceback (most recent call last):\n        File \"/usr/local/lib/python3.10/dist-packages/pip/_vendor/pyproject_hooks/_in_process/_in_process.py\", line 389, in <module>\n          main()\n        File \"/usr/local/lib/python3.10/dist-packages/pip/_vendor/pyproject_hooks/_in_process/_in_process.py\", line 373, in main\n          json_out[\"return_val\"] = hook(**hook_input[\"kwargs\"])\n        File \"/usr/local/lib/python3.10/dist-packages/pip/_vendor/pyproject_hooks/_in_process/_in_process.py\", line 209, in prepare_metadata_for_build_editable\n          return hook(metadata_directory, config_settings)\n        File \"/usr/local/lib/python3.10/dist-packages/scikit_build_core/build/__init__.py\", line 108, in prepare_metadata_for_build_editable\n          return _build_wheel_impl(\n        File \"/usr/local/lib/python3.10/dist-packages/scikit_build_core/build/wheel.py\", line 176, in _build_wheel_impl\n          return _build_wheel_impl_impl(\n        File \"/usr/local/lib/python3.10/dist-packages/scikit_build_core/build/wheel.py\", line 248, in _build_wheel_impl_impl\n          cmake = CMake.default_search(version=settings.cmake.version, env=os.environ)\n        File \"/usr/local/lib/python3.10/dist-packages/scikit_build_core/cmake.py\", line 67, in default_search\n          raise CMakeNotFoundError(msg)\n      scikit_build_core.errors.CMakeNotFoundError: Could not find CMake with version >=3.21\n      [end of output]\n  \n  note: This error originates from a subprocess, and is likely not a problem with pip.\nerror: metadata-generation-failed\n\n× Encountered error while generating package metadata.\n╰─> See above for output.\n\nnote: This is an issue with the package mentioned above, not pip.\nhint: See above for details.\n",
    "execution_time": 0.5510845184326172
  },
  {
    "command": "pytest",
    "success": false,
    "stdout": "============================= test session starts ==============================\nplatform linux -- Python 3.10.12, pytest-8.4.1, pluggy-1.6.0\nrootdir: /app/repo_to_process\ncollected 0 items / 1 error\n\n==================================== ERRORS ====================================\n_________________________ ERROR collecting python/test _________________________\n/usr/lib/python3.10/importlib/__init__.py:126: in import_module\n    return _bootstrap._gcd_import(name[level:], package, level)\n<frozen importlib._bootstrap>:1050: in _gcd_import\n    ???\n<frozen importlib._bootstrap>:1027: in _find_and_load\n    ???\n<frozen importlib._bootstrap>:1006: in _find_and_load_unlocked\n    ???\n<frozen importlib._bootstrap>:688: in _load_unlocked\n    ???\n/usr/local/lib/python3.10/dist-packages/_pytest/assertion/rewrite.py:186: in exec_module\n    exec(co, module.__dict__)\npython/test/conftest.py:13: in <module>\n    from dolfinx.la import vector as dolfinx_vector\nE   ModuleNotFoundError: No module named 'dolfinx'\n=========================== short test summary info ============================\nERROR python/test - ModuleNotFoundError: No module named 'dolfinx'\n!!!!!!!!!!!!!!!!!!!! Interrupted: 1 error during collection !!!!!!!!!!!!!!!!!!!!\n=============================== 1 error in 0.53s ===============================\n",
    "stderr": "",
    "execution_time": 0.7778692245483398
  }
]