[
  {
    "command": "pip install matplotlib pdfrw",
    "success": true,
    "stdout": "Looking in indexes: https://repo.huaweicloud.com/repository/pypi/simple/\nCollecting matplotlib\n  Downloading https://repo.huaweicloud.com/repository/pypi/packages/ac/64/8d0c8937dee86c286625bddb1902efacc3e22f2b619f5b5a8df29fe5217b/matplotlib-3.10.5-cp310-cp310-manylinux2014_x86_64.manylinux_2_17_x86_64.whl (8.7 MB)\n     ━━━━━━━━━━━━━━━━━━━━━━━━━━━━━━━━━━━━━━━━ 8.7/8.7 MB 13.2 MB/s  0:00:00\nCollecting pdfrw\n  Downloading https://repo.huaweicloud.com/repository/pypi/packages/c0/84/af442c4458756bb0c0d2424102d1200616f3ff9b82c48aaa130e08549bf6/pdfrw-0.4-py2.py3-none-any.whl (69 kB)\nCollecting contourpy>=1.0.1 (from matplotlib)\n  Downloading https://repo.huaweicloud.com/repository/pypi/packages/32/5c/1ee32d1c7956923202f00cf8d2a14a62ed7517bdc0ee1e55301227fc273c/contourpy-1.3.2-cp310-cp310-manylinux_2_17_x86_64.manylinux2014_x86_64.whl (325 kB)\nCollecting cycler>=0.10 (from matplotlib)\n  Downloading https://repo.huaweicloud.com/repository/pypi/packages/e7/05/c19819d5e3d95294a6f5947fb9b9629efb316b96de511b418c53d245aae6/cycler-0.12.1-py3-none-any.whl (8.3 kB)\nCollecting fonttools>=4.22.0 (from matplotlib)\n  Downloading https://repo.huaweicloud.com/repository/pypi/packages/05/57/767e31e48861045d89691128bd81fd4c62b62150f9a17a666f731ce4f197/fonttools-4.59.0-cp310-cp310-manylinux2014_x86_64.manylinux_2_17_x86_64.whl (4.8 MB)\n     ━━━━━━━━━━━━━━━━━━━━━━━━━━━━━━━━━━━━━━━━ 4.8/4.8 MB 15.7 MB/s  0:00:00\nCollecting kiwisolver>=1.3.1 (from matplotlib)\n  Downloading https://repo.huaweicloud.com/repository/pypi/packages/d4/42/0f333164e6307a0687d1eb9ad256215aae2f4bd5d28f4653d6cd319a3ba3/kiwisolver-1.4.9-cp310-cp310-manylinux_2_12_x86_64.manylinux2010_x86_64.whl (1.6 MB)\n     ━━━━━━━━━━━━━━━━━━━━━━━━━━━━━━━━━━━━━━━━ 1.6/1.6 MB 11.2 MB/s  0:00:00\nCollecting numpy>=1.23 (from matplotlib)\n  Downloading https://repo.huaweicloud.com/repository/pypi/packages/b4/63/3de6a34ad7ad6646ac7d2f55ebc6ad439dbbf9c4370017c50cf403fb19b5/numpy-2.2.6-cp310-cp310-manylinux_2_17_x86_64.manylinux2014_x86_64.whl (16.8 MB)\n     ━━━━━━━━━━━━━━━━━━━━━━━━━━━━━━━━━━━━━━━━ 16.8/16.8 MB 15.3 MB/s  0:00:01\nRequirement already satisfied: packaging>=20.0 in /usr/local/lib/python3.10/dist-packages (from matplotlib) (25.0)\nRequirement already satisfied: pillow>=8 in /usr/local/lib/python3.10/dist-packages (from matplotlib) (11.3.0)\nRequirement already satisfied: pyparsing>=2.3.1 in /usr/local/lib/python3.10/dist-packages (from matplotlib) (3.2.3)\nRequirement already satisfied: python-dateutil>=2.7 in /usr/local/lib/python3.10/dist-packages (from matplotlib) (2.9.0.post0)\nRequirement already satisfied: six>=1.5 in /usr/local/lib/python3.10/dist-packages (from python-dateutil>=2.7->matplotlib) (1.17.0)\nInstalling collected packages: pdfrw, numpy, kiwisolver, fonttools, cycler, contourpy, matplotlib\n  Attempting uninstall: numpy\n    Found existing installation: numpy 1.22.4\n    Uninstalling numpy-1.22.4:\n      Successfully uninstalled numpy-1.22.4\n\nSuccessfully installed contourpy-1.3.2 cycler-0.12.1 fonttools-4.59.0 kiwisolver-1.4.9 matplotlib-3.10.5 numpy-2.2.6 pdfrw-0.4\n",
    "stderr": "ERROR: pip's dependency resolver does not currently take into account all the packages that are installed. This behaviour is the source of the following dependency conflicts.\nnumba 0.60.0 requires numpy<2.1,>=1.22, but you have numpy 2.2.6 which is incompatible.\nscipy 1.9.1 requires numpy<1.25.0,>=1.18.5, but you have numpy 2.2.6 which is incompatible.\nWARNING: Running pip as the 'root' user can result in broken permissions and conflicting behaviour with the system package manager, possibly rendering your system unusable. It is recommended to use a virtual environment instead: https://pip.pypa.io/warnings/venv. Use the --root-user-action option if you know what you are doing and want to suppress this warning.\n",
    "execution_time": 10.168632507324219
  },
  {
    "command": "pytest",
    "success": false,
    "stdout": "============================= test session starts ==============================\nplatform linux -- Python 3.10.12, pytest-8.4.1, pluggy-1.6.0\nrootdir: /app/repo_to_process\nconfigfile: pyproject.toml\nplugins: dash-3.2.0, anyio-4.10.0\ncollected 1500 items / 18 errors\n\n==================================== ERRORS ====================================\n_____ ERROR collecting plotly/matplotlylib/mplexporter/tests/test_utils.py _____\nImportError while importing test module '/app/repo_to_process/plotly/matplotlylib/mplexporter/tests/test_utils.py'.\nHint: make sure your test modules/packages have valid Python names.\nTraceback:\n/usr/lib/python3.10/importlib/__init__.py:126: in import_module\n    return _bootstrap._gcd_import(name[level:], package, level)\nplotly/matplotlylib/mplexporter/tests/test_utils.py:2: in <module>\n    from . import plt\nE   ImportError: cannot import name 'plt' from 'plotly.matplotlylib.mplexporter.tests' (/app/repo_to_process/plotly/matplotlylib/mplexporter/tests/__init__.py)\n__________ ERROR collecting tests/test_io/test_to_from_plotly_json.py __________\ntests/test_io/test_to_from_plotly_json.py:4: in <module>\n    import plotly.express as px\nplotly/express/__init__.py:27: in <module>\n    from ._imshow import imshow\nplotly/express/_imshow.py:11: in <module>\n    import xarray\n/usr/local/lib/python3.10/dist-packages/xarray/__init__.py:1: in <module>\n    from . import testing, tutorial\n/usr/local/lib/python3.10/dist-packages/xarray/testing.py:7: in <module>\n    import pandas as pd\n/usr/local/lib/python3.10/dist-packages/pandas/__init__.py:22: in <module>\n    from pandas.compat import is_numpy_dev as _is_numpy_dev\n/usr/local/lib/python3.10/dist-packages/pandas/compat/__init__.py:14: in <module>\n    from pandas.compat.numpy import (\n/usr/local/lib/python3.10/dist-packages/pandas/compat/numpy/__init__.py:4: in <module>\n    from pandas.util.version import Version\n/usr/local/lib/python3.10/dist-packages/pandas/util/__init__.py:1: in <module>\n    from pandas.util._decorators import (  # noqa:F401\n/usr/local/lib/python3.10/dist-packages/pandas/util/_decorators.py:14: in <module>\n    from pandas._libs.properties import cache_readonly  # noqa:F401\n/usr/local/lib/python3.10/dist-packages/pandas/_libs/__init__.py:13: in <module>\n    from pandas._libs.interval import Interval\npandas/_libs/interval.pyx:1: in init pandas._libs.interval\n    ???\nE   ValueError: numpy.dtype size changed, may indicate binary incompatibility. Expected 96 from C header, got 88 from PyObject\n_ ERROR collecting tests/test_optional/test_autoshapes/test_axis_span_shapes.py _\ntests/test_optional/test_autoshapes/test_axis_span_shapes.py:3: in <module>\n    import plotly.express as px\nplotly/express/__init__.py:27: in <module>\n    from ._imshow import imshow\nplotly/express/_imshow.py:11: in <module>\n    import xarray\n/usr/local/lib/python3.10/dist-packages/xarray/__init__.py:1: in <module>\n    from . import testing, tutorial\n/usr/local/lib/python3.10/dist-packages/xarray/testing.py:7: in <module>\n    import pandas as pd\n/usr/local/lib/python3.10/dist-packages/pandas/__init__.py:22: in <module>\n    from pandas.compat import is_numpy_dev as _is_numpy_dev\n/usr/local/lib/python3.10/dist-packages/pandas/compat/__init__.py:14: in <module>\n    from pandas.compat.numpy import (\n/usr/local/lib/python3.10/dist-packages/pandas/compat/numpy/__init__.py:4: in <module>\n    from pandas.util.version import Version\n/usr/local/lib/python3.10/dist-packages/pandas/util/__init__.py:1: in <module>\n    from pandas.util._decorators import (  # noqa:F401\n/usr/local/lib/python3.10/dist-packages/pandas/util/_decorators.py:14: in <module>\n    from pandas._libs.properties import cache_readonly  # noqa:F401\n/usr/local/lib/python3.10/dist-packages/pandas/_libs/__init__.py:13: in <module>\n    from pandas._libs.interval import Interval\npandas/_libs/interval.pyx:1: in init pandas._libs.interval\n    ???\nE   ValueError: numpy.dtype size changed, may indicate binary incompatibility. Expected 96 from C header, got 88 from PyObject\n_ ERROR collecting tests/test_optional/test_figure_factory/test_figure_factory.py _\ntests/test_optional/test_figure_factory/test_figure_factory.py:7: in <module>\n    from ...test_optional.test_utils.test_utils import np_inf\n<frozen importlib._bootstrap>:1027: in _find_and_load\n    ???\n<frozen importlib._bootstrap>:1006: in _find_and_load_unlocked\n    ???\n<frozen importlib._bootstrap>:688: in _load_unlocked\n    ???\n/usr/local/lib/python3.10/dist-packages/_pytest/assertion/rewrite.py:186: in exec_module\n    exec(co, module.__dict__)\ntests/test_optional/test_utils/test_utils.py:15: in <module>\n    import pandas as pd\n/usr/local/lib/python3.10/dist-packages/pandas/__init__.py:22: in <module>\n    from pandas.compat import is_numpy_dev as _is_numpy_dev\n/usr/local/lib/python3.10/dist-packages/pandas/compat/__init__.py:14: in <module>\n    from pandas.compat.numpy import (\n/usr/local/lib/python3.10/dist-packages/pandas/compat/numpy/__init__.py:4: in <module>\n    from pandas.util.version import Version\n/usr/local/lib/python3.10/dist-packages/pandas/util/__init__.py:1: in <module>\n    from pandas.util._decorators import (  # noqa:F401\n/usr/local/lib/python3.10/dist-packages/pandas/util/_decorators.py:14: in <module>\n    from pandas._libs.properties import cache_readonly  # noqa:F401\n/usr/local/lib/python3.10/dist-packages/pandas/_libs/__init__.py:13: in <module>\n    from pandas._libs.interval import Interval\npandas/_libs/interval.pyx:1: in init pandas._libs.interval\n    ???\nE   ValueError: numpy.dtype size changed, may indicate binary incompatibility. Expected 96 from C header, got 88 from PyObject\n__ ERROR collecting tests/test_optional/test_matplotlylib/test_date_times.py ___\ntests/test_optional/test_matplotlylib/test_date_times.py:6: in <module>\n    import pandas as pd\n/usr/local/lib/python3.10/dist-packages/pandas/__init__.py:22: in <module>\n    from pandas.compat import is_numpy_dev as _is_numpy_dev\n/usr/local/lib/python3.10/dist-packages/pandas/compat/__init__.py:14: in <module>\n    from pandas.compat.numpy import (\n/usr/local/lib/python3.10/dist-packages/pandas/compat/numpy/__init__.py:4: in <module>\n    from pandas.util.version import Version\n/usr/local/lib/python3.10/dist-packages/pandas/util/__init__.py:1: in <module>\n    from pandas.util._decorators import (  # noqa:F401\n/usr/local/lib/python3.10/dist-packages/pandas/util/_decorators.py:14: in <module>\n    from pandas._libs.properties import cache_readonly  # noqa:F401\n/usr/local/lib/python3.10/dist-packages/pandas/_libs/__init__.py:13: in <module>\n    from pandas._libs.interval import Interval\npandas/_libs/interval.pyx:1: in init pandas._libs.interval\n    ???\nE   ValueError: numpy.dtype size changed, may indicate binary incompatibility. Expected 96 from C header, got 88 from PyObject\n_________________ ERROR collecting tests/test_optional/test_px _________________\n/usr/lib/python3.10/importlib/__init__.py:126: in import_module\n    return _bootstrap._gcd_import(name[level:], package, level)\n<frozen importlib._bootstrap>:1050: in _gcd_import\n    ???\n<frozen importlib._bootstrap>:1027: in _find_and_load\n    ???\n<frozen importlib._bootstrap>:1006: in _find_and_load_unlocked\n    ???\n<frozen importlib._bootstrap>:688: in _load_unlocked\n    ???\n/usr/local/lib/python3.10/dist-packages/_pytest/assertion/rewrite.py:186: in exec_module\n    exec(co, module.__dict__)\ntests/test_optional/test_px/conftest.py:1: in <module>\n    import pandas as pd\n/usr/local/lib/python3.10/dist-packages/pandas/__init__.py:22: in <module>\n    from pandas.compat import is_numpy_dev as _is_numpy_dev\n/usr/local/lib/python3.10/dist-packages/pandas/compat/__init__.py:14: in <module>\n    from pandas.compat.numpy import (\n/usr/local/lib/python3.10/dist-packages/pandas/compat/numpy/__init__.py:4: in <module>\n    from pandas.util.version import Version\n/usr/local/lib/python3.10/dist-packages/pandas/util/__init__.py:1: in <module>\n    from pandas.util._decorators import (  # noqa:F401\n/usr/local/lib/python3.10/dist-packages/pandas/util/_decorators.py:14: in <module>\n    from pandas._libs.properties import cache_readonly  # noqa:F401\n/usr/local/lib/python3.10/dist-packages/pandas/_libs/__init__.py:13: in <module>\n    from pandas._libs.interval import Interval\npandas/_libs/interval.pyx:1: in init pandas._libs.interval\n    ???\nE   ValueError: numpy.dtype size changed, may indicate binary incompatibility. Expected 96 from C header, got 88 from PyObject\n________ ERROR collecting tests/test_optional/test_utils/test_utils.py _________\ntests/test_optional/test_utils/test_utils.py:15: in <module>\n    import pandas as pd\n/usr/local/lib/python3.10/dist-packages/pandas/__init__.py:22: in <module>\n    from pandas.compat import is_numpy_dev as _is_numpy_dev\n/usr/local/lib/python3.10/dist-packages/pandas/compat/__init__.py:14: in <module>\n    from pandas.compat.numpy import (\n/usr/local/lib/python3.10/dist-packages/pandas/compat/numpy/__init__.py:4: in <module>\n    from pandas.util.version import Version\n/usr/local/lib/python3.10/dist-packages/pandas/util/__init__.py:1: in <module>\n    from pandas.util._decorators import (  # noqa:F401\n/usr/local/lib/python3.10/dist-packages/pandas/util/_decorators.py:14: in <module>\n    from pandas._libs.properties import cache_readonly  # noqa:F401\n/usr/local/lib/python3.10/dist-packages/pandas/_libs/__init__.py:13: in <module>\n    from pandas._libs.interval import Interval\npandas/_libs/interval.pyx:1: in init pandas._libs.interval\n    ???\nE   ValueError: numpy.dtype size changed, may indicate binary incompatibility. Expected 96 from C header, got 88 from PyObject\n__ ERROR collecting tests/test_plotly_utils/validators/test_any_validator.py ___\ntests/test_plotly_utils/validators/test_any_validator.py:4: in <module>\n    from ...test_optional.test_utils.test_utils import np_nan, np_inf\n<frozen importlib._bootstrap>:1027: in _find_and_load\n    ???\n<frozen importlib._bootstrap>:1006: in _find_and_load_unlocked\n    ???\n<frozen importlib._bootstrap>:688: in _load_unlocked\n    ???\n/usr/local/lib/python3.10/dist-packages/_pytest/assertion/rewrite.py:186: in exec_module\n    exec(co, module.__dict__)\ntests/test_optional/test_utils/test_utils.py:15: in <module>\n    import pandas as pd\n/usr/local/lib/python3.10/dist-packages/pandas/__init__.py:22: in <module>\n    from pandas.compat import is_numpy_dev as _is_numpy_dev\n/usr/local/lib/python3.10/dist-packages/pandas/compat/__init__.py:14: in <module>\n    from pandas.compat.numpy import (\n/usr/local/lib/python3.10/dist-packages/pandas/compat/numpy/__init__.py:4: in <module>\n    from pandas.util.version import Version\n/usr/local/lib/python3.10/dist-packages/pandas/util/__init__.py:1: in <module>\n    from pandas.util._decorators import (  # noqa:F401\n/usr/local/lib/python3.10/dist-packages/pandas/util/_decorators.py:14: in <module>\n    from pandas._libs.properties import cache_readonly  # noqa:F401\n/usr/local/lib/python3.10/dist-packages/pandas/_libs/__init__.py:13: in <module>\n    from pandas._libs.interval import Interval\npandas/_libs/interval.pyx:1: in init pandas._libs.interval\n    ???\nE   ValueError: numpy.dtype size changed, may indicate binary incompatibility. Expected 96 from C header, got 88 from PyObject\n_ ERROR collecting tests/test_plotly_utils/validators/test_boolean_validator.py _\ntests/test_plotly_utils/validators/test_boolean_validator.py:3: in <module>\n    from ...test_optional.test_utils.test_utils import np_nan\n<frozen importlib._bootstrap>:1027: in _find_and_load\n    ???\n<frozen importlib._bootstrap>:1006: in _find_and_load_unlocked\n    ???\n<frozen importlib._bootstrap>:688: in _load_unlocked\n    ???\n/usr/local/lib/python3.10/dist-packages/_pytest/assertion/rewrite.py:186: in exec_module\n    exec(co, module.__dict__)\ntests/test_optional/test_utils/test_utils.py:15: in <module>\n    import pandas as pd\n/usr/local/lib/python3.10/dist-packages/pandas/__init__.py:22: in <module>\n    from pandas.compat import is_numpy_dev as _is_numpy_dev\n/usr/local/lib/python3.10/dist-packages/pandas/compat/__init__.py:14: in <module>\n    from pandas.compat.numpy import (\n/usr/local/lib/python3.10/dist-packages/pandas/compat/numpy/__init__.py:4: in <module>\n    from pandas.util.version import Version\n/usr/local/lib/python3.10/dist-packages/pandas/util/__init__.py:1: in <module>\n    from pandas.util._decorators import (  # noqa:F401\n/usr/local/lib/python3.10/dist-packages/pandas/util/_decorators.py:14: in <module>\n    from pandas._libs.properties import cache_readonly  # noqa:F401\n/usr/local/lib/python3.10/dist-packages/pandas/_libs/__init__.py:13: in <module>\n    from pandas._libs.interval import Interval\npandas/_libs/interval.pyx:1: in init pandas._libs.interval\n    ???\nE   ValueError: numpy.dtype size changed, may indicate binary incompatibility. Expected 96 from C header, got 88 from PyObject\n_ ERROR collecting tests/test_plotly_utils/validators/test_dataarray_validator.py _\ntests/test_plotly_utils/validators/test_dataarray_validator.py:4: in <module>\n    import pandas as pd\n/usr/local/lib/python3.10/dist-packages/pandas/__init__.py:22: in <module>\n    from pandas.compat import is_numpy_dev as _is_numpy_dev\n/usr/local/lib/python3.10/dist-packages/pandas/compat/__init__.py:14: in <module>\n    from pandas.compat.numpy import (\n/usr/local/lib/python3.10/dist-packages/pandas/compat/numpy/__init__.py:4: in <module>\n    from pandas.util.version import Version\n/usr/local/lib/python3.10/dist-packages/pandas/util/__init__.py:1: in <module>\n    from pandas.util._decorators import (  # noqa:F401\n/usr/local/lib/python3.10/dist-packages/pandas/util/_decorators.py:14: in <module>\n    from pandas._libs.properties import cache_readonly  # noqa:F401\n/usr/local/lib/python3.10/dist-packages/pandas/_libs/__init__.py:13: in <module>\n    from pandas._libs.interval import Interval\npandas/_libs/interval.pyx:1: in init pandas._libs.interval\n    ???\nE   ValueError: numpy.dtype size changed, may indicate binary incompatibility. Expected 96 from C header, got 88 from PyObject\n_ ERROR collecting tests/test_plotly_utils/validators/test_enumerated_validator.py _\ntests/test_plotly_utils/validators/test_enumerated_validator.py:3: in <module>\n    import pandas as pd\n/usr/local/lib/python3.10/dist-packages/pandas/__init__.py:22: in <module>\n    from pandas.compat import is_numpy_dev as _is_numpy_dev\n/usr/local/lib/python3.10/dist-packages/pandas/compat/__init__.py:14: in <module>\n    from pandas.compat.numpy import (\n/usr/local/lib/python3.10/dist-packages/pandas/compat/numpy/__init__.py:4: in <module>\n    from pandas.util.version import Version\n/usr/local/lib/python3.10/dist-packages/pandas/util/__init__.py:1: in <module>\n    from pandas.util._decorators import (  # noqa:F401\n/usr/local/lib/python3.10/dist-packages/pandas/util/_decorators.py:14: in <module>\n    from pandas._libs.properties import cache_readonly  # noqa:F401\n/usr/local/lib/python3.10/dist-packages/pandas/_libs/__init__.py:13: in <module>\n    from pandas._libs.interval import Interval\npandas/_libs/interval.pyx:1: in init pandas._libs.interval\n    ???\nE   ValueError: numpy.dtype size changed, may indicate binary incompatibility. Expected 96 from C header, got 88 from PyObject\n___ ERROR collecting tests/test_plotly_utils/validators/test_fig_deepcopy.py ___\ntests/test_plotly_utils/validators/test_fig_deepcopy.py:3: in <module>\n    import plotly.express as px\nplotly/express/__init__.py:27: in <module>\n    from ._imshow import imshow\nplotly/express/_imshow.py:11: in <module>\n    import xarray\n/usr/local/lib/python3.10/dist-packages/xarray/__init__.py:1: in <module>\n    from . import testing, tutorial\n/usr/local/lib/python3.10/dist-packages/xarray/testing.py:7: in <module>\n    import pandas as pd\n/usr/local/lib/python3.10/dist-packages/pandas/__init__.py:22: in <module>\n    from pandas.compat import is_numpy_dev as _is_numpy_dev\n/usr/local/lib/python3.10/dist-packages/pandas/compat/__init__.py:14: in <module>\n    from pandas.compat.numpy import (\n/usr/local/lib/python3.10/dist-packages/pandas/compat/numpy/__init__.py:4: in <module>\n    from pandas.util.version import Version\n/usr/local/lib/python3.10/dist-packages/pandas/util/__init__.py:1: in <module>\n    from pandas.util._decorators import (  # noqa:F401\n/usr/local/lib/python3.10/dist-packages/pandas/util/_decorators.py:14: in <module>\n    from pandas._libs.properties import cache_readonly  # noqa:F401\n/usr/local/lib/python3.10/dist-packages/pandas/_libs/__init__.py:13: in <module>\n    from pandas._libs.interval import Interval\npandas/_libs/interval.pyx:1: in init pandas._libs.interval\n    ???\nE   ValueError: numpy.dtype size changed, may indicate binary incompatibility. Expected 96 from C header, got 88 from PyObject\n_ ERROR collecting tests/test_plotly_utils/validators/test_integer_validator.py _\ntests/test_plotly_utils/validators/test_integer_validator.py:6: in <module>\n    import pandas as pd\n/usr/local/lib/python3.10/dist-packages/pandas/__init__.py:22: in <module>\n    from pandas.compat import is_numpy_dev as _is_numpy_dev\n/usr/local/lib/python3.10/dist-packages/pandas/compat/__init__.py:14: in <module>\n    from pandas.compat.numpy import (\n/usr/local/lib/python3.10/dist-packages/pandas/compat/numpy/__init__.py:4: in <module>\n    from pandas.util.version import Version\n/usr/local/lib/python3.10/dist-packages/pandas/util/__init__.py:1: in <module>\n    from pandas.util._decorators import (  # noqa:F401\n/usr/local/lib/python3.10/dist-packages/pandas/util/_decorators.py:14: in <module>\n    from pandas._libs.properties import cache_readonly  # noqa:F401\n/usr/local/lib/python3.10/dist-packages/pandas/_libs/__init__.py:13: in <module>\n    from pandas._libs.interval import Interval\npandas/_libs/interval.pyx:1: in init pandas._libs.interval\n    ???\nE   ValueError: numpy.dtype size changed, may indicate binary incompatibility. Expected 96 from C header, got 88 from PyObject\n_ ERROR collecting tests/test_plotly_utils/validators/test_number_validator.py _\ntests/test_plotly_utils/validators/test_number_validator.py:6: in <module>\n    import pandas as pd\n/usr/local/lib/python3.10/dist-packages/pandas/__init__.py:22: in <module>\n    from pandas.compat import is_numpy_dev as _is_numpy_dev\n/usr/local/lib/python3.10/dist-packages/pandas/compat/__init__.py:14: in <module>\n    from pandas.compat.numpy import (\n/usr/local/lib/python3.10/dist-packages/pandas/compat/numpy/__init__.py:4: in <module>\n    from pandas.util.version import Version\n/usr/local/lib/python3.10/dist-packages/pandas/util/__init__.py:1: in <module>\n    from pandas.util._decorators import (  # noqa:F401\n/usr/local/lib/python3.10/dist-packages/pandas/util/_decorators.py:14: in <module>\n    from pandas._libs.properties import cache_readonly  # noqa:F401\n/usr/local/lib/python3.10/dist-packages/pandas/_libs/__init__.py:13: in <module>\n    from pandas._libs.interval import Interval\npandas/_libs/interval.pyx:1: in init pandas._libs.interval\n    ???\nE   ValueError: numpy.dtype size changed, may indicate binary incompatibility. Expected 96 from C header, got 88 from PyObject\n_ ERROR collecting tests/test_plotly_utils/validators/test_pandas_series_input.py _\ntests/test_plotly_utils/validators/test_pandas_series_input.py:3: in <module>\n    import pandas as pd\n/usr/local/lib/python3.10/dist-packages/pandas/__init__.py:22: in <module>\n    from pandas.compat import is_numpy_dev as _is_numpy_dev\n/usr/local/lib/python3.10/dist-packages/pandas/compat/__init__.py:14: in <module>\n    from pandas.compat.numpy import (\n/usr/local/lib/python3.10/dist-packages/pandas/compat/numpy/__init__.py:4: in <module>\n    from pandas.util.version import Version\n/usr/local/lib/python3.10/dist-packages/pandas/util/__init__.py:1: in <module>\n    from pandas.util._decorators import (  # noqa:F401\n/usr/local/lib/python3.10/dist-packages/pandas/util/_decorators.py:14: in <module>\n    from pandas._libs.properties import cache_readonly  # noqa:F401\n/usr/local/lib/python3.10/dist-packages/pandas/_libs/__init__.py:13: in <module>\n    from pandas._libs.interval import Interval\npandas/_libs/interval.pyx:1: in init pandas._libs.interval\n    ???\nE   ValueError: numpy.dtype size changed, may indicate binary incompatibility. Expected 96 from C header, got 88 from PyObject\n_ ERROR collecting tests/test_plotly_utils/validators/test_string_validator.py _\ntests/test_plotly_utils/validators/test_string_validator.py:5: in <module>\n    from ...test_optional.test_utils.test_utils import np_nan\n<frozen importlib._bootstrap>:1027: in _find_and_load\n    ???\n<frozen importlib._bootstrap>:1006: in _find_and_load_unlocked\n    ???\n<frozen importlib._bootstrap>:688: in _load_unlocked\n    ???\n/usr/local/lib/python3.10/dist-packages/_pytest/assertion/rewrite.py:186: in exec_module\n    exec(co, module.__dict__)\ntests/test_optional/test_utils/test_utils.py:15: in <module>\n    import pandas as pd\n/usr/local/lib/python3.10/dist-packages/pandas/__init__.py:22: in <module>\n    from pandas.compat import is_numpy_dev as _is_numpy_dev\n/usr/local/lib/python3.10/dist-packages/pandas/compat/__init__.py:14: in <module>\n    from pandas.compat.numpy import (\n/usr/local/lib/python3.10/dist-packages/pandas/compat/numpy/__init__.py:4: in <module>\n    from pandas.util.version import Version\n/usr/local/lib/python3.10/dist-packages/pandas/util/__init__.py:1: in <module>\n    from pandas.util._decorators import (  # noqa:F401\n/usr/local/lib/python3.10/dist-packages/pandas/util/_decorators.py:14: in <module>\n    from pandas._libs.properties import cache_readonly  # noqa:F401\n/usr/local/lib/python3.10/dist-packages/pandas/_libs/__init__.py:13: in <module>\n    from pandas._libs.interval import Interval\npandas/_libs/interval.pyx:1: in init pandas._libs.interval\n    ???\nE   ValueError: numpy.dtype size changed, may indicate binary incompatibility. Expected 96 from C header, got 88 from PyObject\n_ ERROR collecting tests/test_plotly_utils/validators/test_subplotid_validator.py _\ntests/test_plotly_utils/validators/test_subplotid_validator.py:3: in <module>\n    from ...test_optional.test_utils.test_utils import np_nan, np_inf\n<frozen importlib._bootstrap>:1027: in _find_and_load\n    ???\n<frozen importlib._bootstrap>:1006: in _find_and_load_unlocked\n    ???\n<frozen importlib._bootstrap>:688: in _load_unlocked\n    ???\n/usr/local/lib/python3.10/dist-packages/_pytest/assertion/rewrite.py:186: in exec_module\n    exec(co, module.__dict__)\ntests/test_optional/test_utils/test_utils.py:15: in <module>\n    import pandas as pd\n/usr/local/lib/python3.10/dist-packages/pandas/__init__.py:22: in <module>\n    from pandas.compat import is_numpy_dev as _is_numpy_dev\n/usr/local/lib/python3.10/dist-packages/pandas/compat/__init__.py:14: in <module>\n    from pandas.compat.numpy import (\n/usr/local/lib/python3.10/dist-packages/pandas/compat/numpy/__init__.py:4: in <module>\n    from pandas.util.version import Version\n/usr/local/lib/python3.10/dist-packages/pandas/util/__init__.py:1: in <module>\n    from pandas.util._decorators import (  # noqa:F401\n/usr/local/lib/python3.10/dist-packages/pandas/util/_decorators.py:14: in <module>\n    from pandas._libs.properties import cache_readonly  # noqa:F401\n/usr/local/lib/python3.10/dist-packages/pandas/_libs/__init__.py:13: in <module>\n    from pandas._libs.interval import Interval\npandas/_libs/interval.pyx:1: in init pandas._libs.interval\n    ???\nE   ValueError: numpy.dtype size changed, may indicate binary incompatibility. Expected 96 from C header, got 88 from PyObject\n___ ERROR collecting tests/test_plotly_utils/validators/test_xarray_input.py ___\ntests/test_plotly_utils/validators/test_xarray_input.py:3: in <module>\n    import xarray\n/usr/local/lib/python3.10/dist-packages/xarray/__init__.py:1: in <module>\n    from . import testing, tutorial\n/usr/local/lib/python3.10/dist-packages/xarray/testing.py:7: in <module>\n    import pandas as pd\n/usr/local/lib/python3.10/dist-packages/pandas/__init__.py:22: in <module>\n    from pandas.compat import is_numpy_dev as _is_numpy_dev\n/usr/local/lib/python3.10/dist-packages/pandas/compat/__init__.py:14: in <module>\n    from pandas.compat.numpy import (\n/usr/local/lib/python3.10/dist-packages/pandas/compat/numpy/__init__.py:4: in <module>\n    from pandas.util.version import Version\n/usr/local/lib/python3.10/dist-packages/pandas/util/__init__.py:1: in <module>\n    from pandas.util._decorators import (  # noqa:F401\n/usr/local/lib/python3.10/dist-packages/pandas/util/_decorators.py:14: in <module>\n    from pandas._libs.properties import cache_readonly  # noqa:F401\n/usr/local/lib/python3.10/dist-packages/pandas/_libs/__init__.py:13: in <module>\n    from pandas._libs.interval import Interval\npandas/_libs/interval.pyx:1: in init pandas._libs.interval\n    ???\nE   ValueError: numpy.dtype size changed, may indicate binary incompatibility. Expected 96 from C header, got 88 from PyObject\n=============================== warnings summary ===============================\nplotly/conftest.py:4\n  /app/repo_to_process/plotly/conftest.py:4: PytestRemovedIn9Warning:\n  \n  The (path: py.path.local) argument is deprecated, please use (collection_path: pathlib.Path)\n  see https://docs.pytest.org/en/latest/deprecations.html#py-path-local-arguments-for-hooks-replaced-with-pathlib-path\n\n../../usr/local/lib/python3.10/dist-packages/scipy/__init__.py:155\n  /usr/local/lib/python3.10/dist-packages/scipy/__init__.py:155: UserWarning:\n  \n  A NumPy version >=1.18.5 and <1.25.0 is required for this version of SciPy (detected version 2.2.6\n\n-- Docs: https://docs.pytest.org/en/stable/how-to/capture-warnings.html\n=========================== short test summary info ============================\nERROR plotly/matplotlylib/mplexporter/tests/test_utils.py\nERROR tests/test_io/test_to_from_plotly_json.py - ValueError: numpy.dtype siz...\nERROR tests/test_optional/test_autoshapes/test_axis_span_shapes.py - ValueErr...\nERROR tests/test_optional/test_figure_factory/test_figure_factory.py - ValueE...\nERROR tests/test_optional/test_matplotlylib/test_date_times.py - ValueError: ...\nERROR tests/test_optional/test_px - ValueError: numpy.dtype size changed, may...\nERROR tests/test_optional/test_utils/test_utils.py - ValueError: numpy.dtype ...\nERROR tests/test_plotly_utils/validators/test_any_validator.py - ValueError: ...\nERROR tests/test_plotly_utils/validators/test_boolean_validator.py - ValueErr...\nERROR tests/test_plotly_utils/validators/test_dataarray_validator.py - ValueE...\nERROR tests/test_plotly_utils/validators/test_enumerated_validator.py - Value...\nERROR tests/test_plotly_utils/validators/test_fig_deepcopy.py - ValueError: n...\nERROR tests/test_plotly_utils/validators/test_integer_validator.py - ValueErr...\nERROR tests/test_plotly_utils/validators/test_number_validator.py - ValueErro...\nERROR tests/test_plotly_utils/validators/test_pandas_series_input.py - ValueE...\nERROR tests/test_plotly_utils/validators/test_string_validator.py - ValueErro...\nERROR tests/test_plotly_utils/validators/test_subplotid_validator.py - ValueE...\nERROR tests/test_plotly_utils/validators/test_xarray_input.py - ValueError: n...\n!!!!!!!!!!!!!!!!!!! Interrupted: 18 errors during collection !!!!!!!!!!!!!!!!!!!\n======================== 2 warnings, 18 errors in 2.62s ========================\n",
    "stderr": "",
    "execution_time": 3.859400987625122
  }
]