[
  {
    "command": "pip install \"numpy==1.24.4\"",
    "success": true,
    "stdout": "Looking in indexes: https://repo.huaweicloud.com/repository/pypi/simple/\nCollecting numpy==1.24.4\n  Downloading https://repo.huaweicloud.com/repository/pypi/packages/10/be/ae5bf4737cb79ba437879915791f6f26d92583c738d7d960ad94e5c36adf/numpy-1.24.4-cp310-cp310-manylinux_2_17_x86_64.manylinux2014_x86_64.whl (17.3 MB)\n     ━━━━━━━━━━━━━━━━━━━━━━━━━━━━━━━━━━━━━━━━ 17.3/17.3 MB 14.6 MB/s  0:00:01\nInstalling collected packages: numpy\n  Attempting uninstall: numpy\n    Found existing installation: numpy 2.2.6\n    Uninstalling numpy-2.2.6:\n      Successfully uninstalled numpy-2.2.6\nSuccessfully installed numpy-1.24.4\n",
    "stderr": "WARNING: Running pip as the 'root' user can result in broken permissions and conflicting behaviour with the system package manager, possibly rendering your system unusable. It is recommended to use a virtual environment instead: https://pip.pypa.io/warnings/venv. Use the --root-user-action option if you know what you are doing and want to suppress this warning.\n",
    "execution_time": 4.461633205413818
  },
  {
    "command": "pip install --force-reinstall --no-cache-dir pandas==2.0.3 scipy numba xarray",
    "success": true,
    "stdout": "Looking in indexes: https://repo.huaweicloud.com/repository/pypi/simple/\nCollecting pandas==2.0.3\n  Downloading https://repo.huaweicloud.com/repository/pypi/packages/e3/59/35a2892bf09ded9c1bf3804461efe772836a5261ef5dfb4e264ce813ff99/pandas-2.0.3-cp310-cp310-manylinux_2_17_x86_64.manylinux2014_x86_64.whl (12.3 MB)\n     ━━━━━━━━━━━━━━━━━━━━━━━━━━━━━━━━━━━━━━━━ 12.3/12.3 MB 15.3 MB/s  0:00:00\nCollecting scipy\n  Downloading https://repo.huaweicloud.com/repository/pypi/packages/8e/6d/41991e503e51fc1134502694c5fa7a1671501a17ffa12716a4a9151af3df/scipy-1.15.3-cp310-cp310-manylinux_2_17_x86_64.manylinux2014_x86_64.whl (37.7 MB)\n     ━━━━━━━━━━━━━━━━━━━━━━━━━━━━━━━━━━━━━━━━ 37.7/37.7 MB 15.6 MB/s  0:00:02\nCollecting numba\n  Downloading https://repo.huaweicloud.com/repository/pypi/packages/e2/7d/bfb2805bcfbd479f04f835241ecf28519f6e3609912e3a985aed45e21370/numba-0.61.2-cp310-cp310-manylinux2014_x86_64.manylinux_2_17_x86_64.whl (3.8 MB)\n     ━━━━━━━━━━━━━━━━━━━━━━━━━━━━━━━━━━━━━━━━ 3.8/3.8 MB 14.8 MB/s  0:00:00\nCollecting xarray\n  Downloading https://repo.huaweicloud.com/repository/pypi/packages/82/8a/6b50c1dd2260d407c1a499d47cf829f59f07007e0dcebafdabb24d1d26a5/xarray-2025.6.1-py3-none-any.whl (1.3 MB)\n     ━━━━━━━━━━━━━━━━━━━━━━━━━━━━━━━━━━━━━━━━ 1.3/1.3 MB 16.1 MB/s  0:00:00\nCollecting python-dateutil>=2.8.2 (from pandas==2.0.3)\n  Downloading https://repo.huaweicloud.com/repository/pypi/packages/ec/57/56b9bcc3c9c6a792fcbaf139543cee77261f3651ca9da0c93f5c1221264b/python_dateutil-2.9.0.post0-py2.py3-none-any.whl (229 kB)\nCollecting pytz>=2020.1 (from pandas==2.0.3)\n  Downloading https://repo.huaweicloud.com/repository/pypi/packages/81/c4/34e93fe5f5429d7570ec1fa436f1986fb1f00c3e0f43a589fe2bbcd22c3f/pytz-2025.2-py2.py3-none-any.whl (509 kB)\nCollecting tzdata>=2022.1 (from pandas==2.0.3)\n  Downloading https://repo.huaweicloud.com/repository/pypi/packages/5c/23/c7abc0ca0a1526a0774eca151daeb8de62ec457e77262b66b359c3c7679e/tzdata-2025.2-py2.py3-none-any.whl (347 kB)\nCollecting numpy>=1.21.0 (from pandas==2.0.3)\n  Downloading https://repo.huaweicloud.com/repository/pypi/packages/b4/63/3de6a34ad7ad6646ac7d2f55ebc6ad439dbbf9c4370017c50cf403fb19b5/numpy-2.2.6-cp310-cp310-manylinux_2_17_x86_64.manylinux2014_x86_64.whl (16.8 MB)\n     ━━━━━━━━━━━━━━━━━━━━━━━━━━━━━━━━━━━━━━━━ 16.8/16.8 MB 15.2 MB/s  0:00:01\nCollecting llvmlite<0.45,>=0.44.0dev0 (from numba)\n  Downloading https://repo.huaweicloud.com/repository/pypi/packages/aa/46/8ffbc114def88cc698906bf5acab54ca9fdf9214fe04aed0e71731fb3688/llvmlite-0.44.0-cp310-cp310-manylinux_2_17_x86_64.manylinux2014_x86_64.whl (42.4 MB)\n     ━━━━━━━━━━━━━━━━━━━━━━━━━━━━━━━━━━━━━━━━ 42.4/42.4 MB 11.7 MB/s  0:00:03\nCollecting packaging>=23.2 (from xarray)\n  Downloading https://repo.huaweicloud.com/repository/pypi/packages/20/12/38679034af332785aac8774540895e234f4d07f7545804097de4b666afd8/packaging-25.0-py3-none-any.whl (66 kB)\nINFO: pip is looking at multiple versions of xarray to determine which version is compatible with other requirements. This could take a while.\nCollecting xarray\n  Downloading https://repo.huaweicloud.com/repository/pypi/packages/57/ed/e737a1c9be5d654b71524ee19ea22376c4d81c50ef2bb5598c9dada74e9a/xarray-2025.6.0-py3-none-any.whl (1.3 MB)\n     ━━━━━━━━━━━━━━━━━━━━━━━━━━━━━━━━━━━━━━━━ 1.3/1.3 MB 15.0 MB/s  0:00:00\n  Downloading https://repo.huaweicloud.com/repository/pypi/packages/a4/1e/96fd96419fec1a37da998a1ca3d558f2cae2f6f3cd5015170371b05a2b6b/xarray-2025.4.0-py3-none-any.whl (1.3 MB)\n     ━━━━━━━━━━━━━━━━━━━━━━━━━━━━━━━━━━━━━━━━ 1.3/1.3 MB 16.9 MB/s  0:00:00\n  Downloading https://repo.huaweicloud.com/repository/pypi/packages/91/fd/973deafd9f87085136a58573600646b408ae7af47859f35151f0d83d5090/xarray-2025.3.1-py3-none-any.whl (1.3 MB)\n     ━━━━━━━━━━━━━━━━━━━━━━━━━━━━━━━━━━━━━━━━ 1.3/1.3 MB 13.5 MB/s  0:00:00\n  Downloading https://repo.huaweicloud.com/repository/pypi/packages/91/19/5dbac77ca82f009f8267d0e7cca4fd3be2a435d83ed98f6f8b9c5cb1747e/xarray-2025.3.0-py3-none-any.whl (1.3 MB)\n     ━━━━━━━━━━━━━━━━━━━━━━━━━━━━━━━━━━━━━━━━ 1.3/1.3 MB 14.4 MB/s  0:00:00\n  Downloading https://repo.huaweicloud.com/repository/pypi/packages/05/79/4e19100342fe13d69fd6e77b343e2269924fec681258e2ea21b55576aad2/xarray-2025.1.2-py3-none-any.whl (1.2 MB)\n     ━━━━━━━━━━━━━━━━━━━━━━━━━━━━━━━━━━━━━━━━ 1.2/1.2 MB 13.0 MB/s  0:00:00\n  Downloading https://repo.huaweicloud.com/repository/pypi/packages/14/78/cd4d5294e0a7294243d332fdd00a020942faa41472e694f2552976a5fe39/xarray-2025.1.1-py3-none-any.whl (1.2 MB)\n     ━━━━━━━━━━━━━━━━━━━━━━━━━━━━━━━━━━━━━━━━ 1.2/1.2 MB 13.8 MB/s  0:00:00\n  Downloading https://repo.huaweicloud.com/repository/pypi/packages/ca/a8/2c2d85b3695804a23bc48171655f7427d1befdc20f0e91dde98334f8d0f7/xarray-2025.1.0-py3-none-any.whl (1.2 MB)\n     ━━━━━━━━━━━━━━━━━━━━━━━━━━━━━━━━━━━━━━━━ 1.2/1.2 MB 14.3 MB/s  0:00:00\nINFO: pip is still looking at multiple versions of xarray to determine which version is compatible with other requirements. This could take a while.\n  Downloading https://repo.huaweicloud.com/repository/pypi/packages/40/ed/1c4631ad5909487ea8907cd326d9855c2207d790e3936e77bda48173b8be/xarray-2024.11.0-py3-none-any.whl (1.2 MB)\n     ━━━━━━━━━━━━━━━━━━━━━━━━━━━━━━━━━━━━━━━━ 1.2/1.2 MB 13.7 MB/s  0:00:00\n  Downloading https://repo.huaweicloud.com/repository/pypi/packages/a9/b7/9830def68e5575a24ca6d6f46b285d35ed27860beaa4f72848cd82870253/xarray-2024.10.0-py3-none-any.whl (1.2 MB)\n     ━━━━━━━━━━━━━━━━━━━━━━━━━━━━━━━━━━━━━━━━ 1.2/1.2 MB 13.9 MB/s  0:00:00\n  Downloading https://repo.huaweicloud.com/repository/pypi/packages/94/28/3a6365e45721c7c9078968ed94b4a60076bc31d73b8519021a69b4995b63/xarray-2024.9.0-py3-none-any.whl (1.2 MB)\n     ━━━━━━━━━━━━━━━━━━━━━━━━━━━━━━━━━━━━━━━━ 1.2/1.2 MB 13.7 MB/s  0:00:00\n  Downloading https://repo.huaweicloud.com/repository/pypi/packages/45/95/233e1f9c939f5ba314297315df709e6a5e823bf3cade7211991b15aa65d2/xarray-2024.7.0-py3-none-any.whl (1.2 MB)\n     ━━━━━━━━━━━━━━━━━━━━━━━━━━━━━━━━━━━━━━━━ 1.2/1.2 MB 10.3 MB/s  0:00:00\nCollecting six>=1.5 (from python-dateutil>=2.8.2->pandas==2.0.3)\n  Downloading https://repo.huaweicloud.com/repository/pypi/packages/b7/ce/149a00dd41f10bc29e5921b496af8b574d8413afcd5e30dfa0ed46c2cc5e/six-1.17.0-py2.py3-none-any.whl (11 kB)\nInstalling collected packages: pytz, tzdata, six, packaging, numpy, llvmlite, scipy, python-dateutil, numba, pandas, xarray\n  Attempting uninstall: pytz\n    Found existing installation: pytz 2025.2\n    Uninstalling pytz-2025.2:\n      Successfully uninstalled pytz-2025.2\n  Attempting uninstall: tzdata\n    Found existing installation: tzdata 2025.2\n    Uninstalling tzdata-2025.2:\n      Successfully uninstalled tzdata-2025.2\n  Attempting uninstall: six\n    Found existing installation: six 1.17.0\n    Uninstalling six-1.17.0:\n      Successfully uninstalled six-1.17.0\n  Attempting uninstall: packaging\n    Found existing installation: packaging 25.0\n    Uninstalling packaging-25.0:\n      Successfully uninstalled packaging-25.0\n  Attempting uninstall: numpy\n    Found existing installation: numpy 1.24.4\n    Uninstalling numpy-1.24.4:\n      Successfully uninstalled numpy-1.24.4\n  Attempting uninstall: llvmlite\n    Found existing installation: llvmlite 0.43.0\n    Uninstalling llvmlite-0.43.0:\n      Successfully uninstalled llvmlite-0.43.0\n  Attempting uninstall: scipy\n    Found existing installation: scipy 1.9.1\n    Uninstalling scipy-1.9.1:\n      Successfully uninstalled scipy-1.9.1\n  Attempting uninstall: python-dateutil\n    Found existing installation: python-dateutil 2.9.0.post0\n    Uninstalling python-dateutil-2.9.0.post0:\n      Successfully uninstalled python-dateutil-2.9.0.post0\n  Attempting uninstall: numba\n    Found existing installation: numba 0.60.0\n    Uninstalling numba-0.60.0:\n      Successfully uninstalled numba-0.60.0\n  Attempting uninstall: pandas\n    Found existing installation: pandas 1.4.0\n    Uninstalling pandas-1.4.0:\n      Successfully uninstalled pandas-1.4.0\n  Attempting uninstall: xarray\n    Found existing installation: xarray 2022.9.0\n    Uninstalling xarray-2022.9.0:\n      Successfully uninstalled xarray-2022.9.0\n\nSuccessfully installed llvmlite-0.44.0 numba-0.61.2 numpy-2.2.6 packaging-25.0 pandas-2.0.3 python-dateutil-2.9.0.post0 pytz-2025.2 scipy-1.15.3 six-1.17.0 tzdata-2025.2 xarray-2024.7.0\n",
    "stderr": "WARNING: Running pip as the 'root' user can result in broken permissions and conflicting behaviour with the system package manager, possibly rendering your system unusable. It is recommended to use a virtual environment instead: https://pip.pypa.io/warnings/venv. Use the --root-user-action option if you know what you are doing and want to suppress this warning.\n",
    "execution_time": 27.922264575958252
  },
  {
    "command": "pytest",
    "success": false,
    "stdout": "============================= test session starts ==============================\nplatform linux -- Python 3.10.12, pytest-8.4.1, pluggy-1.6.0\nrootdir: /app/repo_to_process\nconfigfile: pyproject.toml\nplugins: dash-3.2.0, anyio-4.10.0\ncollected 1500 items / 18 errors\n\n==================================== ERRORS ====================================\n_____ ERROR collecting plotly/matplotlylib/mplexporter/tests/test_utils.py _____\nImportError while importing test module '/app/repo_to_process/plotly/matplotlylib/mplexporter/tests/test_utils.py'.\nHint: make sure your test modules/packages have valid Python names.\nTraceback:\n/usr/lib/python3.10/importlib/__init__.py:126: in import_module\n    return _bootstrap._gcd_import(name[level:], package, level)\nplotly/matplotlylib/mplexporter/tests/test_utils.py:2: in <module>\n    from . import plt\nE   ImportError: cannot import name 'plt' from 'plotly.matplotlylib.mplexporter.tests' (/app/repo_to_process/plotly/matplotlylib/mplexporter/tests/__init__.py)\n__________ ERROR collecting tests/test_io/test_to_from_plotly_json.py __________\ntests/test_io/test_to_from_plotly_json.py:4: in <module>\n    import plotly.express as px\nplotly/express/__init__.py:27: in <module>\n    from ._imshow import imshow\nplotly/express/_imshow.py:11: in <module>\n    import xarray\n/usr/local/lib/python3.10/dist-packages/xarray/__init__.py:3: in <module>\n    from xarray import groupers, testing, tutorial\n/usr/local/lib/python3.10/dist-packages/xarray/groupers.py:15: in <module>\n    import pandas as pd\n/usr/local/lib/python3.10/dist-packages/pandas/__init__.py:22: in <module>\n    from pandas.compat import is_numpy_dev as _is_numpy_dev  # pyright: ignore # noqa:F401\n/usr/local/lib/python3.10/dist-packages/pandas/compat/__init__.py:25: in <module>\n    from pandas.compat.numpy import (\n/usr/local/lib/python3.10/dist-packages/pandas/compat/numpy/__init__.py:4: in <module>\n    from pandas.util.version import Version\n/usr/local/lib/python3.10/dist-packages/pandas/util/__init__.py:2: in <module>\n    from pandas.util._decorators import (  # noqa:F401\n/usr/local/lib/python3.10/dist-packages/pandas/util/_decorators.py:14: in <module>\n    from pandas._libs.properties import cache_readonly\n/usr/local/lib/python3.10/dist-packages/pandas/_libs/__init__.py:13: in <module>\n    from pandas._libs.interval import Interval\npandas/_libs/interval.pyx:1: in init pandas._libs.interval\n    ???\nE   ValueError: numpy.dtype size changed, may indicate binary incompatibility. Expected 96 from C header, got 88 from PyObject\n_ ERROR collecting tests/test_optional/test_autoshapes/test_axis_span_shapes.py _\ntests/test_optional/test_autoshapes/test_axis_span_shapes.py:3: in <module>\n    import plotly.express as px\nplotly/express/__init__.py:27: in <module>\n    from ._imshow import imshow\nplotly/express/_imshow.py:11: in <module>\n    import xarray\n/usr/local/lib/python3.10/dist-packages/xarray/__init__.py:3: in <module>\n    from xarray import groupers, testing, tutorial\n/usr/local/lib/python3.10/dist-packages/xarray/groupers.py:15: in <module>\n    import pandas as pd\n/usr/local/lib/python3.10/dist-packages/pandas/__init__.py:22: in <module>\n    from pandas.compat import is_numpy_dev as _is_numpy_dev  # pyright: ignore # noqa:F401\n/usr/local/lib/python3.10/dist-packages/pandas/compat/__init__.py:25: in <module>\n    from pandas.compat.numpy import (\n/usr/local/lib/python3.10/dist-packages/pandas/compat/numpy/__init__.py:4: in <module>\n    from pandas.util.version import Version\n/usr/local/lib/python3.10/dist-packages/pandas/util/__init__.py:2: in <module>\n    from pandas.util._decorators import (  # noqa:F401\n/usr/local/lib/python3.10/dist-packages/pandas/util/_decorators.py:14: in <module>\n    from pandas._libs.properties import cache_readonly\n/usr/local/lib/python3.10/dist-packages/pandas/_libs/__init__.py:13: in <module>\n    from pandas._libs.interval import Interval\npandas/_libs/interval.pyx:1: in init pandas._libs.interval\n    ???\nE   ValueError: numpy.dtype size changed, may indicate binary incompatibility. Expected 96 from C header, got 88 from PyObject\n_ ERROR collecting tests/test_optional/test_figure_factory/test_figure_factory.py _\ntests/test_optional/test_figure_factory/test_figure_factory.py:7: in <module>\n    from ...test_optional.test_utils.test_utils import np_inf\n<frozen importlib._bootstrap>:1027: in _find_and_load\n    ???\n<frozen importlib._bootstrap>:1006: in _find_and_load_unlocked\n    ???\n<frozen importlib._bootstrap>:688: in _load_unlocked\n    ???\n/usr/local/lib/python3.10/dist-packages/_pytest/assertion/rewrite.py:186: in exec_module\n    exec(co, module.__dict__)\ntests/test_optional/test_utils/test_utils.py:15: in <module>\n    import pandas as pd\n/usr/local/lib/python3.10/dist-packages/pandas/__init__.py:22: in <module>\n    from pandas.compat import is_numpy_dev as _is_numpy_dev  # pyright: ignore # noqa:F401\n/usr/local/lib/python3.10/dist-packages/pandas/compat/__init__.py:25: in <module>\n    from pandas.compat.numpy import (\n/usr/local/lib/python3.10/dist-packages/pandas/compat/numpy/__init__.py:4: in <module>\n    from pandas.util.version import Version\n/usr/local/lib/python3.10/dist-packages/pandas/util/__init__.py:2: in <module>\n    from pandas.util._decorators import (  # noqa:F401\n/usr/local/lib/python3.10/dist-packages/pandas/util/_decorators.py:14: in <module>\n    from pandas._libs.properties import cache_readonly\n/usr/local/lib/python3.10/dist-packages/pandas/_libs/__init__.py:13: in <module>\n    from pandas._libs.interval import Interval\npandas/_libs/interval.pyx:1: in init pandas._libs.interval\n    ???\nE   ValueError: numpy.dtype size changed, may indicate binary incompatibility. Expected 96 from C header, got 88 from PyObject\n__ ERROR collecting tests/test_optional/test_matplotlylib/test_date_times.py ___\ntests/test_optional/test_matplotlylib/test_date_times.py:6: in <module>\n    import pandas as pd\n/usr/local/lib/python3.10/dist-packages/pandas/__init__.py:22: in <module>\n    from pandas.compat import is_numpy_dev as _is_numpy_dev  # pyright: ignore # noqa:F401\n/usr/local/lib/python3.10/dist-packages/pandas/compat/__init__.py:25: in <module>\n    from pandas.compat.numpy import (\n/usr/local/lib/python3.10/dist-packages/pandas/compat/numpy/__init__.py:4: in <module>\n    from pandas.util.version import Version\n/usr/local/lib/python3.10/dist-packages/pandas/util/__init__.py:2: in <module>\n    from pandas.util._decorators import (  # noqa:F401\n/usr/local/lib/python3.10/dist-packages/pandas/util/_decorators.py:14: in <module>\n    from pandas._libs.properties import cache_readonly\n/usr/local/lib/python3.10/dist-packages/pandas/_libs/__init__.py:13: in <module>\n    from pandas._libs.interval import Interval\npandas/_libs/interval.pyx:1: in init pandas._libs.interval\n    ???\nE   ValueError: numpy.dtype size changed, may indicate binary incompatibility. Expected 96 from C header, got 88 from PyObject\n_________________ ERROR collecting tests/test_optional/test_px _________________\n/usr/lib/python3.10/importlib/__init__.py:126: in import_module\n    return _bootstrap._gcd_import(name[level:], package, level)\n<frozen importlib._bootstrap>:1050: in _gcd_import\n    ???\n<frozen importlib._bootstrap>:1027: in _find_and_load\n    ???\n<frozen importlib._bootstrap>:1006: in _find_and_load_unlocked\n    ???\n<frozen importlib._bootstrap>:688: in _load_unlocked\n    ???\n/usr/local/lib/python3.10/dist-packages/_pytest/assertion/rewrite.py:186: in exec_module\n    exec(co, module.__dict__)\ntests/test_optional/test_px/conftest.py:1: in <module>\n    import pandas as pd\n/usr/local/lib/python3.10/dist-packages/pandas/__init__.py:22: in <module>\n    from pandas.compat import is_numpy_dev as _is_numpy_dev  # pyright: ignore # noqa:F401\n/usr/local/lib/python3.10/dist-packages/pandas/compat/__init__.py:25: in <module>\n    from pandas.compat.numpy import (\n/usr/local/lib/python3.10/dist-packages/pandas/compat/numpy/__init__.py:4: in <module>\n    from pandas.util.version import Version\n/usr/local/lib/python3.10/dist-packages/pandas/util/__init__.py:2: in <module>\n    from pandas.util._decorators import (  # noqa:F401\n/usr/local/lib/python3.10/dist-packages/pandas/util/_decorators.py:14: in <module>\n    from pandas._libs.properties import cache_readonly\n/usr/local/lib/python3.10/dist-packages/pandas/_libs/__init__.py:13: in <module>\n    from pandas._libs.interval import Interval\npandas/_libs/interval.pyx:1: in init pandas._libs.interval\n    ???\nE   ValueError: numpy.dtype size changed, may indicate binary incompatibility. Expected 96 from C header, got 88 from PyObject\n________ ERROR collecting tests/test_optional/test_utils/test_utils.py _________\ntests/test_optional/test_utils/test_utils.py:15: in <module>\n    import pandas as pd\n/usr/local/lib/python3.10/dist-packages/pandas/__init__.py:22: in <module>\n    from pandas.compat import is_numpy_dev as _is_numpy_dev  # pyright: ignore # noqa:F401\n/usr/local/lib/python3.10/dist-packages/pandas/compat/__init__.py:25: in <module>\n    from pandas.compat.numpy import (\n/usr/local/lib/python3.10/dist-packages/pandas/compat/numpy/__init__.py:4: in <module>\n    from pandas.util.version import Version\n/usr/local/lib/python3.10/dist-packages/pandas/util/__init__.py:2: in <module>\n    from pandas.util._decorators import (  # noqa:F401\n/usr/local/lib/python3.10/dist-packages/pandas/util/_decorators.py:14: in <module>\n    from pandas._libs.properties import cache_readonly\n/usr/local/lib/python3.10/dist-packages/pandas/_libs/__init__.py:13: in <module>\n    from pandas._libs.interval import Interval\npandas/_libs/interval.pyx:1: in init pandas._libs.interval\n    ???\nE   ValueError: numpy.dtype size changed, may indicate binary incompatibility. Expected 96 from C header, got 88 from PyObject\n__ ERROR collecting tests/test_plotly_utils/validators/test_any_validator.py ___\ntests/test_plotly_utils/validators/test_any_validator.py:4: in <module>\n    from ...test_optional.test_utils.test_utils import np_nan, np_inf\n<frozen importlib._bootstrap>:1027: in _find_and_load\n    ???\n<frozen importlib._bootstrap>:1006: in _find_and_load_unlocked\n    ???\n<frozen importlib._bootstrap>:688: in _load_unlocked\n    ???\n/usr/local/lib/python3.10/dist-packages/_pytest/assertion/rewrite.py:186: in exec_module\n    exec(co, module.__dict__)\ntests/test_optional/test_utils/test_utils.py:15: in <module>\n    import pandas as pd\n/usr/local/lib/python3.10/dist-packages/pandas/__init__.py:22: in <module>\n    from pandas.compat import is_numpy_dev as _is_numpy_dev  # pyright: ignore # noqa:F401\n/usr/local/lib/python3.10/dist-packages/pandas/compat/__init__.py:25: in <module>\n    from pandas.compat.numpy import (\n/usr/local/lib/python3.10/dist-packages/pandas/compat/numpy/__init__.py:4: in <module>\n    from pandas.util.version import Version\n/usr/local/lib/python3.10/dist-packages/pandas/util/__init__.py:2: in <module>\n    from pandas.util._decorators import (  # noqa:F401\n/usr/local/lib/python3.10/dist-packages/pandas/util/_decorators.py:14: in <module>\n    from pandas._libs.properties import cache_readonly\n/usr/local/lib/python3.10/dist-packages/pandas/_libs/__init__.py:13: in <module>\n    from pandas._libs.interval import Interval\npandas/_libs/interval.pyx:1: in init pandas._libs.interval\n    ???\nE   ValueError: numpy.dtype size changed, may indicate binary incompatibility. Expected 96 from C header, got 88 from PyObject\n_ ERROR collecting tests/test_plotly_utils/validators/test_boolean_validator.py _\ntests/test_plotly_utils/validators/test_boolean_validator.py:3: in <module>\n    from ...test_optional.test_utils.test_utils import np_nan\n<frozen importlib._bootstrap>:1027: in _find_and_load\n    ???\n<frozen importlib._bootstrap>:1006: in _find_and_load_unlocked\n    ???\n<frozen importlib._bootstrap>:688: in _load_unlocked\n    ???\n/usr/local/lib/python3.10/dist-packages/_pytest/assertion/rewrite.py:186: in exec_module\n    exec(co, module.__dict__)\ntests/test_optional/test_utils/test_utils.py:15: in <module>\n    import pandas as pd\n/usr/local/lib/python3.10/dist-packages/pandas/__init__.py:22: in <module>\n    from pandas.compat import is_numpy_dev as _is_numpy_dev  # pyright: ignore # noqa:F401\n/usr/local/lib/python3.10/dist-packages/pandas/compat/__init__.py:25: in <module>\n    from pandas.compat.numpy import (\n/usr/local/lib/python3.10/dist-packages/pandas/compat/numpy/__init__.py:4: in <module>\n    from pandas.util.version import Version\n/usr/local/lib/python3.10/dist-packages/pandas/util/__init__.py:2: in <module>\n    from pandas.util._decorators import (  # noqa:F401\n/usr/local/lib/python3.10/dist-packages/pandas/util/_decorators.py:14: in <module>\n    from pandas._libs.properties import cache_readonly\n/usr/local/lib/python3.10/dist-packages/pandas/_libs/__init__.py:13: in <module>\n    from pandas._libs.interval import Interval\npandas/_libs/interval.pyx:1: in init pandas._libs.interval\n    ???\nE   ValueError: numpy.dtype size changed, may indicate binary incompatibility. Expected 96 from C header, got 88 from PyObject\n_ ERROR collecting tests/test_plotly_utils/validators/test_dataarray_validator.py _\ntests/test_plotly_utils/validators/test_dataarray_validator.py:4: in <module>\n    import pandas as pd\n/usr/local/lib/python3.10/dist-packages/pandas/__init__.py:22: in <module>\n    from pandas.compat import is_numpy_dev as _is_numpy_dev  # pyright: ignore # noqa:F401\n/usr/local/lib/python3.10/dist-packages/pandas/compat/__init__.py:25: in <module>\n    from pandas.compat.numpy import (\n/usr/local/lib/python3.10/dist-packages/pandas/compat/numpy/__init__.py:4: in <module>\n    from pandas.util.version import Version\n/usr/local/lib/python3.10/dist-packages/pandas/util/__init__.py:2: in <module>\n    from pandas.util._decorators import (  # noqa:F401\n/usr/local/lib/python3.10/dist-packages/pandas/util/_decorators.py:14: in <module>\n    from pandas._libs.properties import cache_readonly\n/usr/local/lib/python3.10/dist-packages/pandas/_libs/__init__.py:13: in <module>\n    from pandas._libs.interval import Interval\npandas/_libs/interval.pyx:1: in init pandas._libs.interval\n    ???\nE   ValueError: numpy.dtype size changed, may indicate binary incompatibility. Expected 96 from C header, got 88 from PyObject\n_ ERROR collecting tests/test_plotly_utils/validators/test_enumerated_validator.py _\ntests/test_plotly_utils/validators/test_enumerated_validator.py:3: in <module>\n    import pandas as pd\n/usr/local/lib/python3.10/dist-packages/pandas/__init__.py:22: in <module>\n    from pandas.compat import is_numpy_dev as _is_numpy_dev  # pyright: ignore # noqa:F401\n/usr/local/lib/python3.10/dist-packages/pandas/compat/__init__.py:25: in <module>\n    from pandas.compat.numpy import (\n/usr/local/lib/python3.10/dist-packages/pandas/compat/numpy/__init__.py:4: in <module>\n    from pandas.util.version import Version\n/usr/local/lib/python3.10/dist-packages/pandas/util/__init__.py:2: in <module>\n    from pandas.util._decorators import (  # noqa:F401\n/usr/local/lib/python3.10/dist-packages/pandas/util/_decorators.py:14: in <module>\n    from pandas._libs.properties import cache_readonly\n/usr/local/lib/python3.10/dist-packages/pandas/_libs/__init__.py:13: in <module>\n    from pandas._libs.interval import Interval\npandas/_libs/interval.pyx:1: in init pandas._libs.interval\n    ???\nE   ValueError: numpy.dtype size changed, may indicate binary incompatibility. Expected 96 from C header, got 88 from PyObject\n___ ERROR collecting tests/test_plotly_utils/validators/test_fig_deepcopy.py ___\ntests/test_plotly_utils/validators/test_fig_deepcopy.py:3: in <module>\n    import plotly.express as px\nplotly/express/__init__.py:27: in <module>\n    from ._imshow import imshow\nplotly/express/_imshow.py:11: in <module>\n    import xarray\n/usr/local/lib/python3.10/dist-packages/xarray/__init__.py:3: in <module>\n    from xarray import groupers, testing, tutorial\n/usr/local/lib/python3.10/dist-packages/xarray/groupers.py:15: in <module>\n    import pandas as pd\n/usr/local/lib/python3.10/dist-packages/pandas/__init__.py:22: in <module>\n    from pandas.compat import is_numpy_dev as _is_numpy_dev  # pyright: ignore # noqa:F401\n/usr/local/lib/python3.10/dist-packages/pandas/compat/__init__.py:25: in <module>\n    from pandas.compat.numpy import (\n/usr/local/lib/python3.10/dist-packages/pandas/compat/numpy/__init__.py:4: in <module>\n    from pandas.util.version import Version\n/usr/local/lib/python3.10/dist-packages/pandas/util/__init__.py:2: in <module>\n    from pandas.util._decorators import (  # noqa:F401\n/usr/local/lib/python3.10/dist-packages/pandas/util/_decorators.py:14: in <module>\n    from pandas._libs.properties import cache_readonly\n/usr/local/lib/python3.10/dist-packages/pandas/_libs/__init__.py:13: in <module>\n    from pandas._libs.interval import Interval\npandas/_libs/interval.pyx:1: in init pandas._libs.interval\n    ???\nE   ValueError: numpy.dtype size changed, may indicate binary incompatibility. Expected 96 from C header, got 88 from PyObject\n_ ERROR collecting tests/test_plotly_utils/validators/test_integer_validator.py _\ntests/test_plotly_utils/validators/test_integer_validator.py:6: in <module>\n    import pandas as pd\n/usr/local/lib/python3.10/dist-packages/pandas/__init__.py:22: in <module>\n    from pandas.compat import is_numpy_dev as _is_numpy_dev  # pyright: ignore # noqa:F401\n/usr/local/lib/python3.10/dist-packages/pandas/compat/__init__.py:25: in <module>\n    from pandas.compat.numpy import (\n/usr/local/lib/python3.10/dist-packages/pandas/compat/numpy/__init__.py:4: in <module>\n    from pandas.util.version import Version\n/usr/local/lib/python3.10/dist-packages/pandas/util/__init__.py:2: in <module>\n    from pandas.util._decorators import (  # noqa:F401\n/usr/local/lib/python3.10/dist-packages/pandas/util/_decorators.py:14: in <module>\n    from pandas._libs.properties import cache_readonly\n/usr/local/lib/python3.10/dist-packages/pandas/_libs/__init__.py:13: in <module>\n    from pandas._libs.interval import Interval\npandas/_libs/interval.pyx:1: in init pandas._libs.interval\n    ???\nE   ValueError: numpy.dtype size changed, may indicate binary incompatibility. Expected 96 from C header, got 88 from PyObject\n_ ERROR collecting tests/test_plotly_utils/validators/test_number_validator.py _\ntests/test_plotly_utils/validators/test_number_validator.py:6: in <module>\n    import pandas as pd\n/usr/local/lib/python3.10/dist-packages/pandas/__init__.py:22: in <module>\n    from pandas.compat import is_numpy_dev as _is_numpy_dev  # pyright: ignore # noqa:F401\n/usr/local/lib/python3.10/dist-packages/pandas/compat/__init__.py:25: in <module>\n    from pandas.compat.numpy import (\n/usr/local/lib/python3.10/dist-packages/pandas/compat/numpy/__init__.py:4: in <module>\n    from pandas.util.version import Version\n/usr/local/lib/python3.10/dist-packages/pandas/util/__init__.py:2: in <module>\n    from pandas.util._decorators import (  # noqa:F401\n/usr/local/lib/python3.10/dist-packages/pandas/util/_decorators.py:14: in <module>\n    from pandas._libs.properties import cache_readonly\n/usr/local/lib/python3.10/dist-packages/pandas/_libs/__init__.py:13: in <module>\n    from pandas._libs.interval import Interval\npandas/_libs/interval.pyx:1: in init pandas._libs.interval\n    ???\nE   ValueError: numpy.dtype size changed, may indicate binary incompatibility. Expected 96 from C header, got 88 from PyObject\n_ ERROR collecting tests/test_plotly_utils/validators/test_pandas_series_input.py _\ntests/test_plotly_utils/validators/test_pandas_series_input.py:3: in <module>\n    import pandas as pd\n/usr/local/lib/python3.10/dist-packages/pandas/__init__.py:22: in <module>\n    from pandas.compat import is_numpy_dev as _is_numpy_dev  # pyright: ignore # noqa:F401\n/usr/local/lib/python3.10/dist-packages/pandas/compat/__init__.py:25: in <module>\n    from pandas.compat.numpy import (\n/usr/local/lib/python3.10/dist-packages/pandas/compat/numpy/__init__.py:4: in <module>\n    from pandas.util.version import Version\n/usr/local/lib/python3.10/dist-packages/pandas/util/__init__.py:2: in <module>\n    from pandas.util._decorators import (  # noqa:F401\n/usr/local/lib/python3.10/dist-packages/pandas/util/_decorators.py:14: in <module>\n    from pandas._libs.properties import cache_readonly\n/usr/local/lib/python3.10/dist-packages/pandas/_libs/__init__.py:13: in <module>\n    from pandas._libs.interval import Interval\npandas/_libs/interval.pyx:1: in init pandas._libs.interval\n    ???\nE   ValueError: numpy.dtype size changed, may indicate binary incompatibility. Expected 96 from C header, got 88 from PyObject\n_ ERROR collecting tests/test_plotly_utils/validators/test_string_validator.py _\ntests/test_plotly_utils/validators/test_string_validator.py:5: in <module>\n    from ...test_optional.test_utils.test_utils import np_nan\n<frozen importlib._bootstrap>:1027: in _find_and_load\n    ???\n<frozen importlib._bootstrap>:1006: in _find_and_load_unlocked\n    ???\n<frozen importlib._bootstrap>:688: in _load_unlocked\n    ???\n/usr/local/lib/python3.10/dist-packages/_pytest/assertion/rewrite.py:186: in exec_module\n    exec(co, module.__dict__)\ntests/test_optional/test_utils/test_utils.py:15: in <module>\n    import pandas as pd\n/usr/local/lib/python3.10/dist-packages/pandas/__init__.py:22: in <module>\n    from pandas.compat import is_numpy_dev as _is_numpy_dev  # pyright: ignore # noqa:F401\n/usr/local/lib/python3.10/dist-packages/pandas/compat/__init__.py:25: in <module>\n    from pandas.compat.numpy import (\n/usr/local/lib/python3.10/dist-packages/pandas/compat/numpy/__init__.py:4: in <module>\n    from pandas.util.version import Version\n/usr/local/lib/python3.10/dist-packages/pandas/util/__init__.py:2: in <module>\n    from pandas.util._decorators import (  # noqa:F401\n/usr/local/lib/python3.10/dist-packages/pandas/util/_decorators.py:14: in <module>\n    from pandas._libs.properties import cache_readonly\n/usr/local/lib/python3.10/dist-packages/pandas/_libs/__init__.py:13: in <module>\n    from pandas._libs.interval import Interval\npandas/_libs/interval.pyx:1: in init pandas._libs.interval\n    ???\nE   ValueError: numpy.dtype size changed, may indicate binary incompatibility. Expected 96 from C header, got 88 from PyObject\n_ ERROR collecting tests/test_plotly_utils/validators/test_subplotid_validator.py _\ntests/test_plotly_utils/validators/test_subplotid_validator.py:3: in <module>\n    from ...test_optional.test_utils.test_utils import np_nan, np_inf\n<frozen importlib._bootstrap>:1027: in _find_and_load\n    ???\n<frozen importlib._bootstrap>:1006: in _find_and_load_unlocked\n    ???\n<frozen importlib._bootstrap>:688: in _load_unlocked\n    ???\n/usr/local/lib/python3.10/dist-packages/_pytest/assertion/rewrite.py:186: in exec_module\n    exec(co, module.__dict__)\ntests/test_optional/test_utils/test_utils.py:15: in <module>\n    import pandas as pd\n/usr/local/lib/python3.10/dist-packages/pandas/__init__.py:22: in <module>\n    from pandas.compat import is_numpy_dev as _is_numpy_dev  # pyright: ignore # noqa:F401\n/usr/local/lib/python3.10/dist-packages/pandas/compat/__init__.py:25: in <module>\n    from pandas.compat.numpy import (\n/usr/local/lib/python3.10/dist-packages/pandas/compat/numpy/__init__.py:4: in <module>\n    from pandas.util.version import Version\n/usr/local/lib/python3.10/dist-packages/pandas/util/__init__.py:2: in <module>\n    from pandas.util._decorators import (  # noqa:F401\n/usr/local/lib/python3.10/dist-packages/pandas/util/_decorators.py:14: in <module>\n    from pandas._libs.properties import cache_readonly\n/usr/local/lib/python3.10/dist-packages/pandas/_libs/__init__.py:13: in <module>\n    from pandas._libs.interval import Interval\npandas/_libs/interval.pyx:1: in init pandas._libs.interval\n    ???\nE   ValueError: numpy.dtype size changed, may indicate binary incompatibility. Expected 96 from C header, got 88 from PyObject\n___ ERROR collecting tests/test_plotly_utils/validators/test_xarray_input.py ___\ntests/test_plotly_utils/validators/test_xarray_input.py:3: in <module>\n    import xarray\n/usr/local/lib/python3.10/dist-packages/xarray/__init__.py:3: in <module>\n    from xarray import groupers, testing, tutorial\n/usr/local/lib/python3.10/dist-packages/xarray/groupers.py:15: in <module>\n    import pandas as pd\n/usr/local/lib/python3.10/dist-packages/pandas/__init__.py:22: in <module>\n    from pandas.compat import is_numpy_dev as _is_numpy_dev  # pyright: ignore # noqa:F401\n/usr/local/lib/python3.10/dist-packages/pandas/compat/__init__.py:25: in <module>\n    from pandas.compat.numpy import (\n/usr/local/lib/python3.10/dist-packages/pandas/compat/numpy/__init__.py:4: in <module>\n    from pandas.util.version import Version\n/usr/local/lib/python3.10/dist-packages/pandas/util/__init__.py:2: in <module>\n    from pandas.util._decorators import (  # noqa:F401\n/usr/local/lib/python3.10/dist-packages/pandas/util/_decorators.py:14: in <module>\n    from pandas._libs.properties import cache_readonly\n/usr/local/lib/python3.10/dist-packages/pandas/_libs/__init__.py:13: in <module>\n    from pandas._libs.interval import Interval\npandas/_libs/interval.pyx:1: in init pandas._libs.interval\n    ???\nE   ValueError: numpy.dtype size changed, may indicate binary incompatibility. Expected 96 from C header, got 88 from PyObject\n=============================== warnings summary ===============================\nplotly/conftest.py:4\n  /app/repo_to_process/plotly/conftest.py:4: PytestRemovedIn9Warning:\n  \n  The (path: py.path.local) argument is deprecated, please use (collection_path: pathlib.Path)\n  see https://docs.pytest.org/en/latest/deprecations.html#py-path-local-arguments-for-hooks-replaced-with-pathlib-path\n\n-- Docs: https://docs.pytest.org/en/stable/how-to/capture-warnings.html\n=========================== short test summary info ============================\nERROR plotly/matplotlylib/mplexporter/tests/test_utils.py\nERROR tests/test_io/test_to_from_plotly_json.py - ValueError: numpy.dtype siz...\nERROR tests/test_optional/test_autoshapes/test_axis_span_shapes.py - ValueErr...\nERROR tests/test_optional/test_figure_factory/test_figure_factory.py - ValueE...\nERROR tests/test_optional/test_matplotlylib/test_date_times.py - ValueError: ...\nERROR tests/test_optional/test_px - ValueError: numpy.dtype size changed, may...\nERROR tests/test_optional/test_utils/test_utils.py - ValueError: numpy.dtype ...\nERROR tests/test_plotly_utils/validators/test_any_validator.py - ValueError: ...\nERROR tests/test_plotly_utils/validators/test_boolean_validator.py - ValueErr...\nERROR tests/test_plotly_utils/validators/test_dataarray_validator.py - ValueE...\nERROR tests/test_plotly_utils/validators/test_enumerated_validator.py - Value...\nERROR tests/test_plotly_utils/validators/test_fig_deepcopy.py - ValueError: n...\nERROR tests/test_plotly_utils/validators/test_integer_validator.py - ValueErr...\nERROR tests/test_plotly_utils/validators/test_number_validator.py - ValueErro...\nERROR tests/test_plotly_utils/validators/test_pandas_series_input.py - ValueE...\nERROR tests/test_plotly_utils/validators/test_string_validator.py - ValueErro...\nERROR tests/test_plotly_utils/validators/test_subplotid_validator.py - ValueE...\nERROR tests/test_plotly_utils/validators/test_xarray_input.py - ValueError: n...\n!!!!!!!!!!!!!!!!!!! Interrupted: 18 errors during collection !!!!!!!!!!!!!!!!!!!\n======================== 1 warning, 18 errors in 2.86s =========================\n",
    "stderr": "",
    "execution_time": 4.301950693130493
  }
]